<?xml version="1.0"?>
<robot name="wheel" xmlns:xacro="http://ros.org/wiki/xacro">

  <xacro:macro name="wheel" params="name x y z flip" >

    <link name="wheel_${name}" >
      <visual>
<!--        <origin xyz="0 0 0" rpy="1.57079632679 ${flip * 3.1415926535} 0" />-->
        <geometry>
          <cylinder radius="${wheel_radius}" length="${wheel_thickness}" />
        </geometry>
      </visual>

      <collision>
<!--        <origin xyz="0 0 0" rpy="1.57079632679 ${flip * 3.1415926535} 0" />-->
        <geometry>
          <cylinder radius="${wheel_radius}" length="${wheel_thickness}" />
        </geometry>
      </collision>

      <inertial>
        <origin xyz="0 0 0" rpy="0 0 0"/>
        <mass value="${wheel_mass}"/>
        <inertia ixx="${wheel_mass/12*(3*wheel_radius*wheel_radius + wheel_thickness*wheel_thickness)}" ixy="0" ixz="0" iyy="${wheel_mass/12*(3*wheel_radius*wheel_radius + wheel_thickness*wheel_thickness)}" iyz="0" izz="${wheel_mass/2 * wheel_radius*wheel_radius}"/>
      </inertial>

    </link>
    <joint name="wheel_${name}_joint" type="continuous" >
      <parent link="base_link" />
      <child link="wheel_${name}" />
      <origin xyz="${x} ${y} ${z}" rpy="-1.57079632679 0 0" />
      <axis xyz="0 0 1" />
      <limit effort="1000.0" velocity="22.0" />
    </joint>

  </xacro:macro>
</robot>